PostgreSQL server information

{'user': 'postgres', 'channel_binding': 'prefer', 'dbname': 'Quotebot', 'host': 'lgjt.xyz', 'port': '5432', 'options': '', 'sslmode': 'prefer', 'sslcompression': '0', 'sslsni': '1', 'ssl_min_protocol_version': 'TLSv1.2', 'gssencmode': 'prefer', 'krbsrvname': 'postgres', 'target_session_attrs': 'any'} 

You are connected to -  ('PostgreSQL 14.2 (Debian 14.2-1.pgdg110+1) on x86_64-pc-linux-gnu, compiled by gcc (Debian 10.2.1-6) 10.2.1 20210110, 64-bit',) 

We have logged in as quoter#2467

We have logged in as quoter#2467

Ignoring exception in command quote:

Traceback (most recent call last):

  File "/usr/local/lib/python3.10/site-packages/nextcord/application_command.py", line 1053, in _call_with_hooks

    await callback(*args)

  File "/usr/local/lib/python3.10/site-packages/nextcord/application_command.py", line 1135, in call_invoke_slash

    await self.invoke_slash(interaction, **kwargs)

  File "/usr/local/lib/python3.10/site-packages/nextcord/application_command.py", line 1228, in invoke_slash

    await self.callback(interaction, **kwargs)

  File "//bot.py", line 24, in quote

    db.add_quote_to_db(quote.lower(), person.lower(), year)

  File "/db.py", line 43, in add_quote_to_db

    cursor.execute("ROLLBACK")

psycopg2.OperationalError: server closed the connection unexpectedly

	This probably means the server terminated abnormally

	before or while processing the request.

The above exception was the direct cause of the following exception:

nextcord.errors.ApplicationInvokeError: Command raised an exception: OperationalError: server closed the connection unexpectedly

	This probably means the server terminated abnormally

	before or while processing the request.

Ignoring exception in command quote:

Traceback (most recent call last):

  File "/usr/local/lib/python3.10/site-packages/nextcord/application_command.py", line 1053, in _call_with_hooks

    await callback(*args)

  File "/usr/local/lib/python3.10/site-packages/nextcord/application_command.py", line 1135, in call_invoke_slash

    await self.invoke_slash(interaction, **kwargs)

  File "/usr/local/lib/python3.10/site-packages/nextcord/application_command.py", line 1228, in invoke_slash

    await self.callback(interaction, **kwargs)

  File "//bot.py", line 24, in quote

    db.add_quote_to_db(quote.lower(), person.lower(), year)

  File "/db.py", line 43, in add_quote_to_db

    cursor.execute("ROLLBACK")

psycopg2.InterfaceError: cursor already closed

The above exception was the direct cause of the following exception:

nextcord.errors.ApplicationInvokeError: Command raised an exception: InterfaceError: cursor already closed